<?xml version="1.0" ?>
<sdf version="1.6">
  <model name="kobra_mk5">
    <pose>0 0 0.0 0 0 0</pose>

    <!-- ************************************************************************ -->
    <!-- CHASSIS LINK *********************************************************** -->
    <!-- ************************************************************************ -->

    <link name="chassis">
      <inertial>
        <mass>1326.0</mass>
        <pose>0 0 0 0 0 0</pose>
        <inertia>
          <ixx>2581.13354740</ixx>
          <ixy>0.0</ixy>
          <iyy>591.30846112</iyy>
          <ixz>0.0</ixz>
          <iyz>0.0</iyz>
          <izz>2681.95008628</izz>
        </inertia>
      </inertial>

      <visual name="chassis_visual">
        <geometry>
          <mesh>
            <uri>model://prius_hybrid/meshes/Hybrid.obj</uri>
            <scale>0.01 0.01 0.01</scale>
            <submesh>
              <name>Hybrid</name>
              <center>false</center>
            </submesh>
          </mesh>
        </geometry>
      </visual>

      <visual name="interior_visual">
        <geometry>
          <mesh>
            <uri>model://prius_hybrid/meshes/Hybrid.obj</uri>
            <scale>0.01 0.01 0.01</scale>
            <submesh>
              <name>Hybrid_Interior</name>
              <center>false</center>
            </submesh>
          </mesh>
        </geometry>
      </visual>

      <visual name="windows_visual">
        <geometry>
          <mesh>
            <uri>model://prius_hybrid/meshes/Hybrid.obj</uri>
            <scale>0.01 0.01 0.01</scale>
            <submesh>
              <name>Hybrid_Windows</name>
              <center>false</center>
            </submesh>
          </mesh>
        </geometry>
      </visual>

      <collision name="chassis_collision">
        <pose>0.0 0.05 0.625 0 0 0</pose>
        <geometry>
          <box>
            <size>1.7526 2.1 0.95</size>
          </box>
        </geometry>
      </collision>

      <collision name="front_bumper">
        <pose>0.0 -2.0 0.458488 0.0 0 0</pose>
        <geometry>
          <box>
            <size>1.337282 0.48 0.566691</size>
          </box>
        </geometry>
      </collision>

      <collision name="hood">
        <pose>0.0 -1.900842 0.676305 0.341247 0 0</pose>
        <geometry>
          <box>
            <size>1.597968 0.493107 0.265468</size>
          </box>
        </geometry>
      </collision>

      <collision name="windshield">
        <pose>0.0 -0.875105 1.032268 0.335476 0 0</pose>
        <geometry>
          <box>
            <size>1.168381 1.654253 0.272347</size>
          </box>
        </geometry>
      </collision>

      <collision name="top_front">
        <pose>0.0 0.161236 1.386042 0.135030 0 0</pose>
        <geometry>
          <box>
            <size>1.279154 0.625988 0.171868</size>
          </box>
        </geometry>
      </collision>

      <collision name="top_rear">
        <pose>0.0 0.817696 1.360069 -0.068997 0 0</pose>
        <geometry>
          <box>
            <size>1.285130 0.771189 0.226557</size>
          </box>
        </geometry>
      </collision>

      <collision name="rear_window">
        <pose>0.0 1.640531 1.175126 -0.262017 0 0</pose>
        <geometry>
          <box>
            <size>1.267845 1.116344 0.244286</size>
          </box>
        </geometry>
      </collision>

      <collision name="trunk">
        <pose>0.0 1.637059 0.888180 0.0 0 0</pose>
        <geometry>
          <box>
            <size>1.788064 1.138988 0.482746</size>
          </box>
        </geometry>
      </collision>

      <collision name="back_bumper">
        <pose>0.0 2.054454 0.577870 0.0 0 0</pose>
        <geometry>
          <box>
            <size>1.781650 0.512093 0.581427</size>
          </box>
        </geometry>
      </collision>
    </link>

    <!-- ************************************************************************ -->
    <!-- WHEEL JOINTS *********************************************************** -->
    <!-- ************************************************************************ -->

    <joint type="universal" name="front_left_combined_joint">
      <pose>0 0 0 0 0 0</pose>
      <child>front_left_wheel</child>
      <parent>chassis</parent>
      <axis>
        <xyz>0 0 1</xyz>
        <limit>
          <!-- +- 50 degrees -->
          <lower>-0.8727</lower>
          <upper>0.8727</upper>
        </limit>
      </axis>
      <axis2>
        <xyz>1 0 0</xyz>
        <dynamics>
          <friction>18.0474092253</friction>
        </dynamics>
      </axis2>
    </joint>

    <joint type="universal" name="front_right_combined_joint">
      <pose>0 0 0 0 0 0</pose>
      <child>front_right_wheel</child>
      <parent>chassis</parent>
      <axis>
        <xyz>0 0 1</xyz>
        <limit>
          <!-- +- 50 degrees -->
          <lower>-0.8727</lower>
          <upper>0.8727</upper>
        </limit>
      </axis>
      <axis2>
        <xyz>1 0 0</xyz>
        <dynamics>
          <friction>18.0474092253</friction>
        </dynamics>
      </axis2>
    </joint>
    
    <joint type="revolute" name="rear_axle_joint">
      <child>rear_axle</child>
      <parent>chassis</parent>
      <axis>
        <xyz>0 1 0</xyz>
        <limit>
          <lower>-0.05089058524173028</lower>
          <upper>0.05089058524173028</upper>
        </limit>
        <dynamics>
          <spring_stiffness>20000.0</spring_stiffness>
          <damping>2000.0</damping>
        </dynamics>
      </axis>
    </joint>

    <joint type="revolute" name="rear_left_wheel_joint">
      <child>rear_left_wheel</child>
      <parent>rear_axle</parent>
      <axis>
        <xyz>1 0 0</xyz>
        <dynamics>
          <friction>12.031606150200002</friction>
        </dynamics>
      </axis>
      <physics>
        <ode>
          <erp>0.2</erp>
          <cfm>0.0</cfm>
        </ode>
      </physics>
    </joint>
    
    <joint type="revolute" name="rear_right_wheel_joint">
      <child>rear_right_wheel</child>
      <parent>rear_axle</parent>
      <axis>
        <xyz>1 0 0</xyz>
        <dynamics>
          <friction>12.031606150200002</friction>
        </dynamics>
      </axis>
      <physics>
        <ode>
          <erp>0.2</erp>
          <cfm>0.0</cfm>
        </ode>
      </physics>
    </joint>

    <joint name="steering_joint" type="revolute">
      <pose>-0.002 0 0 0 0 0</pose>
      <parent>chassis</parent>
      <child>steering_wheel</child>
      <axis>
        <xyz>0 0.964095 0.265556</xyz>
        <limit>
          <lower>-7.85</lower>
          <upper>7.85</upper>
        </limit>
        <dynamics>
          <damping>1.0</damping>
        </dynamics>
        <use_parent_model_frame>true</use_parent_model_frame>
      </axis>
    </joint>

    <!-- ************************************************************************ -->
    <!-- SENSOR JOINTS ********************************************************** -->
    <!-- ************************************************************************ -->

    <joint name='imu_link_joint' type='fixed'>
      <pose>0 1.45 0.3 0 0 0</pose>
      <parent>chassis</parent>
      <child>imu_link</child>
    </joint>

    <joint name='camera_link_joint' type='fixed'>
      <pose>0.0 0.0 0.0 0 0 0</pose>
      <parent>chassis</parent>
      <child>camera_link</child>
    </joint>

    <link name="steering_wheel">
      <pose>0.357734 -0.627868 0.988243 -1.302101 0 0</pose>
      <inertial>
        <mass>1.0</mass>
        <inertia>
          <ixx>0.14583300</ixx>
          <ixy>0</ixy>
          <ixz>0</ixz>
          <iyy>0.14583300</iyy>
          <iyz>0</iyz>
          <izz>0.12500000</izz>
        </inertia>
      </inertial>
      <collision name="collision">
        <geometry>
          <cylinder>
            <radius>0.178172</radius>
            <length>0.041845</length>
          </cylinder>
        </geometry>
        <surface>
          <contact>
            <ode>
              <min_depth>0.003</min_depth>
            </ode>
          </contact>
        </surface>
      </collision>
      <visual name="visual">
        <pose>0 0 0 1.302101 0 0</pose>
        <geometry>
          <mesh>
            <uri>model://prius_hybrid/meshes/Hybrid.obj</uri>
            <scale>0.01 0.01 0.01</scale>
            <submesh>
              <name>Steering_Wheel</name>
              <center>true</center>
            </submesh>
          </mesh>
        </geometry>
      </visual>
    </link>

    <!-- ************************************************************************ -->
    <!-- WHEEL LINKS ************************************************************ -->
    <!-- ************************************************************************ -->

    <link name="front_left_wheel">
      <pose>0.76 -1.41 0.31265 0 0 0</pose>
      <inertial>
        <mass>11</mass>
        <inertia>
          <ixx>0.4301</ixx>
          <ixy>0.0</ixy>
          <iyy>0.4301</iyy>
          <ixz>0.0</ixz>
          <iyz>0.0</iyz>
          <izz>0.4301</izz>
        </inertia>
      </inertial>

      <visual name="front_left_wheel_visual">
        <pose>0 0 0.0 0 0 0</pose>
        <geometry>
          <mesh>
            <uri>model://prius_hybrid/meshes/Hybrid.obj</uri>
            <scale>0.01 0.01 0.01</scale>
            <submesh>
              <name>Wheel_Front_Left_</name>
              <center>true</center>
            </submesh>
          </mesh>
        </geometry>
      </visual>

      <collision name="front_left_wheel_collision">
        <pose>0.0 0.0 0.0 0 1.5707963267948966 0</pose>
        <geometry>
          <sphere>
            <radius>0.31265</radius>
          </sphere>
        </geometry>
        <surface>
          <friction>
            <ode>
              <mu>0.9</mu>
              <mu2>0.9</mu2>
              <slip1>0.0003</slip1>
              <slip2>0.0003</slip2>
            </ode>
            <torsional>
              <coefficient>10.0</coefficient>
              <surface_radius>0.31265</surface_radius>
              <use_patch_radius>false</use_patch_radius>
            </torsional>
          </friction>
          <contact>
            <poissons_ratio>0.5</poissons_ratio>
            <elastic_modulus>1e7</elastic_modulus>
            <ode>
              <min_depth>0.005</min_depth>
              <kp>1e15</kp>
              <kd>1e2</kd>
              <soft_cfm>0</soft_cfm>
              <soft_erp>0.20</soft_erp>
            </ode>
          </contact>
        </surface>
      </collision>

      <sensor name="fl_bumper_plugin" type="contact">
        <always_on>true</always_on>
        <update_rate>100</update_rate>
        <contact>
          <collision>front_left_wheel_collision</collision>
        </contact>
        <plugin name="fl_bumper_plugin" filename="libgazebo_ros_bumper.so">
          <ros>
            <namespace>kobra_mk5</namespace>
            <remapping>bumper_states:=front_left_contact_forces</remapping>
          </ros>
          <bumperTopicName>bumper_topic</bumperTopicName>
          <frameName>front_left_wheel</frameName>
        </plugin>
      </sensor>

    </link>

    <link name="front_right_wheel">
      <pose>-0.76 -1.41 0.31265 0 0 0</pose>
      <inertial>
        <mass>11</mass>
        <inertia>
          <ixx>0.4301</ixx>
          <ixy>0.0</ixy>
          <iyy>0.4301</iyy>
          <ixz>0.0</ixz>
          <iyz>0.0</iyz>
          <izz>0.4301</izz>
        </inertia>
      </inertial>
      <visual name="front_right_wheel_visual">
        <pose>0 0 0.0 0 0 0</pose>
        <geometry>
          <mesh>
            <uri>model://prius_hybrid/meshes/Hybrid.obj</uri>
            <scale>0.01 0.01 0.01</scale>
            <submesh>
              <name>Wheel_Front_Right</name>
              <center>true</center>
            </submesh>
          </mesh>
        </geometry>
      </visual>

      <collision name="front_right_wheel_collision">
        <pose>0.0 0.0 0.0 0 1.5707963267948966 0</pose>
        <geometry>
          <sphere>
            <radius>0.31265</radius>
          </sphere>
        </geometry>
        <surface>
          <friction>
            <ode>
              <mu>0.9</mu>
              <mu2>0.9</mu2>
              <slip1>0.0003</slip1>
              <slip2>0.0003</slip2>
            </ode>
            <torsional>
              <coefficient>10.0</coefficient>
              <surface_radius>0.31265</surface_radius>
              <use_patch_radius>false</use_patch_radius>
            </torsional>
          </friction>
          <contact>
            <poissons_ratio>0.5</poissons_ratio>
            <elastic_modulus>1e7</elastic_modulus>
            <ode>
              <min_depth>0.005</min_depth>
              <kp>1e15</kp>
              <kd>1e2</kd>
              <soft_cfm>0</soft_cfm>
              <soft_erp>0.20</soft_erp>
            </ode>
          </contact>
        </surface>
      </collision>

      <sensor name="fr_bumper_plugin" type="contact">
        <always_on>true</always_on>
        <update_rate>100</update_rate>
        <contact>
          <collision>front_right_wheel_collision</collision>
        </contact>
        <plugin name="fr_bumper_plugin" filename="libgazebo_ros_bumper.so">
          <ros>
            <namespace>kobra_mk5</namespace>
            <remapping>bumper_states:=front_right_contact_forces</remapping>
          </ros>
          <bumperTopicName>bumper_topic</bumperTopicName>
          <frameName>front_right_wheel</frameName>
        </plugin>
      </sensor>

    </link>


    <link name="rear_left_wheel">
      <pose>0.786 1.45 0.31265 0 0 0</pose>
      <inertial>
        <mass>11</mass>
        <inertia>
          <ixx>0.4301</ixx>
          <ixy>0.0</ixy>
          <iyy>0.4301</iyy>
          <ixz>0.0</ixz>
          <iyz>0.0</iyz>
          <izz>0.4301</izz>
        </inertia>
      </inertial>

      <visual name="rear_left_wheel_visual">
        <pose>0.04 0.0 0.0 0 0 0</pose>
        <geometry>
          <mesh>
            <uri>model://prius_hybrid/meshes/Hybrid.obj</uri>
            <scale>0.01 0.01 0.01</scale>
            <submesh>
              <name>Wheel_Front_Left_</name>
              <center>true</center>
            </submesh>
          </mesh>
        </geometry>
      </visual>

      <collision name="rear_left_wheel_collision">
        <pose>0.0 0.0 0.0 0 1.5707963267948966 0</pose>
        <geometry>
          <sphere>
            <radius>0.31265</radius>
          </sphere>
        </geometry>
        <surface>
          <friction>
            <ode>
              <mu>0.9</mu>
              <mu2>0.9</mu2>
              <slip1>0.0003</slip1>
              <slip2>0.0003</slip2>
            </ode>
            <torsional>
              <coefficient>10.0</coefficient>
              <surface_radius>0.31265</surface_radius>
              <use_patch_radius>false</use_patch_radius>
            </torsional>
          </friction>
          <contact>
            <poissons_ratio>0.5</poissons_ratio>
            <elastic_modulus>1e7</elastic_modulus>
            <ode>
              <min_depth>0.005</min_depth>
              <kp>1e15</kp>
              <kd>1e2</kd>
              <soft_cfm>0</soft_cfm>
              <soft_erp>0.20</soft_erp>
            </ode>
          </contact>
        </surface>
      </collision>
      <sensor name="rl_bumper_plugin" type="contact">
        <always_on>true</always_on>
        <update_rate>100</update_rate>
        <contact>
          <collision>rear_left_wheel_collision</collision>
        </contact>
        <plugin name="rl_bumper_plugin" filename="libgazebo_ros_bumper.so">
          <ros>
            <namespace>kobra_mk5</namespace>
            <remapping>bumper_states:=rear_left_contact_forces</remapping>
          </ros>
          <bumperTopicName>bumper_topic</bumperTopicName>
          <frameName>rear_left_wheel</frameName>
        </plugin>
      </sensor>
    </link>


    <link name="rear_right_wheel">
      <pose>-0.786 1.45 0.31265 0 0 0</pose>
      <inertial>
        <mass>11</mass>
        <inertia>
          <ixx>0.4301</ixx>
          <ixy>0.0</ixy>
          <iyy>0.4301</iyy>
          <ixz>0.0</ixz>
          <iyz>0.0</iyz>
          <izz>0.4301</izz>
        </inertia>
      </inertial>
      <visual name="rear_right_wheel_visual">
        <pose>-0.04 0.0 0.0 0 0 0</pose>
        <geometry>
          <mesh>
            <uri>model://prius_hybrid/meshes/Hybrid.obj</uri>
            <scale>0.01 0.01 0.01</scale>
            <submesh>
              <name>Wheel_Front_Right</name>
              <center>true</center>
            </submesh>
          </mesh>
        </geometry>
      </visual>
      <collision name="rear_right_wheel_collision">
        <pose>0.0 0.0 0.0 0 1.5707963267948966 0</pose>
        <geometry>
          <sphere>
            <radius>0.31265</radius>
          </sphere>
        </geometry>
        <surface>
          <friction>
            <ode>
              <mu>0.9</mu>
              <mu2>0.9</mu2>
              <slip1>0.0003</slip1>
              <slip2>0.0003</slip2>
            </ode>
            <torsional>
              <coefficient>10.0</coefficient>
              <surface_radius>0.31265</surface_radius>
              <use_patch_radius>false</use_patch_radius>
            </torsional>
          </friction>
          <contact>
            <poissons_ratio>0.5</poissons_ratio>
            <elastic_modulus>1e7</elastic_modulus>
            <ode>
              <min_depth>0.005</min_depth>
              <kp>1e15</kp>
              <kd>1e2</kd>
              <soft_cfm>0</soft_cfm>
              <soft_erp>0.20</soft_erp>
            </ode>
          </contact>
        </surface>
      </collision>
      <sensor name="rr_bumper_plugin" type="contact">
        <always_on>true</always_on>
        <update_rate>100</update_rate>
        <contact>
          <collision>rear_right_wheel_collision</collision>
        </contact>
        <plugin name="rr_bumper_plugin" filename="libgazebo_ros_bumper.so">
          <ros>
            <namespace>kobra_mk5</namespace>
            <remapping>bumper_states:=rear_right_contact_forces</remapping>
          </ros>
          <bumperTopicName>bumper_topic</bumperTopicName>
          <frameName>rear_right_wheel</frameName>
        </plugin>
      </sensor>
    </link>

    <!-- ************************************************************************ -->
    <!-- REAR AXLE LINK ********************************************************* -->
    <!-- ************************************************************************ -->

    <link name="rear_axle">
      <pose>0 1.45 0.3 0 0 0</pose>
      <inertial>
        <mass>30.0</mass>
        <inertia>
          <ixx>0.08437499999999999</ixx>
          <ixy>0.0</ixy>
          <iyy>4.64581</iyy>
          <ixz>0.0</ixz>
          <iyz>0.0</iyz>
          <izz>4.64581</izz>
        </inertia>
      </inertial>
      <visual name="visual">
        <pose>0.0 0.0 0.0 0 1.5707963267948966 0</pose>
        <geometry>
          <cylinder>
            <length>1.357</length>
            <radius>0.075</radius>
          </cylinder>
        </geometry>
        <material>
          <script>
            <name>Gazebo/Grey</name>
            <uri>file://media/materials/scripts/gazebo.material</uri>
          </script>
        </material>
      </visual>
    </link>

    <!-- ************************************************************************ -->
    <!-- SENSOR LINKS *********************************************************** -->
    <!-- ************************************************************************ -->

    <link name="imu_link">
      <!-- Position of the imu link was moved to rear axle -->
      <pose relative_to="chassis">0 1.45 0.31265 0 0 0</pose> 
      <!-- <pose relative_to="chassis">0 -1.41 0.31265 0 0 0</pose>  -->
      <inertial>
        <pose>0 0 0 0 0 0</pose>
        <mass>1e-8</mass>
        <inertia>
          <ixx>1e-10</ixx>
          <ixy>0</ixy>
          <ixz>0</ixz>
          <iyy>1e-10</iyy>
          <iyz>0</iyz>
          <izz>1e-10</izz>
        </inertia>
      </inertial>      

      <gravity>true</gravity>
    </link>

    <link name="gps_link">
      <pose>0 1.45 0.3 0 0 0</pose>
      <inertial>
        <pose>0 0 0 0 0 0</pose>
        <mass>1e-5</mass>
        <inertia>
          <ixx>1e-6</ixx>
          <ixy>0</ixy>
          <ixz>0</ixz>
          <iyy>1e-6</iyy>
          <iyz>0</iyz>
          <izz>1e-6</izz>
        </inertia>
      </inertial>      
    </link>    

    <!-- ************************************************************************ -->
    <!-- GAZEBO SLIP PLUG-IN **************************************************** -->
    <!-- ************************************************************************ -->

    <plugin filename="libht_nav_gazebo_wheel_surface_plugin.so" name="wheel_surface_plugin">
      <config_params>
        <ContactForceUpdateFreq>100</ContactForceUpdateFreq>
        <!-- link->collision->surface->bounce -->
        <bounce>0.0</bounce>
        <bounceThreshold>0.0</bounceThreshold> 
        <!-- link->collision->surface->friction->ode -->
        <MuPrimary>0.9</MuPrimary> 
        <MuSecondary>0.9</MuSecondary>    
        <slip1>0.0003</slip1>
        <slip2>0.0003</slip2>
        <!-- link->collision->surface->friction->torsional  -->
        <MuTorsion>10.0</MuTorsion> 
        <SurfaceRadius>0.31265</SurfaceRadius> 
        <PatchRadius>0</PatchRadius> 
        <UsePatchRadius>0</UsePatchRadius> 
        <!-- link->collision->surface->friction->contact -->
        <PoissonsRatio>0.5</PoissonsRatio> 
        <ElasticModulus>1e7</ElasticModulus> 
        <minDepth>0.01</minDepth>
        <kp>1e15</kp>
        <kd>1e2</kd>
        <cfm>0.0</cfm>
        <erp>0.2</erp>
        <maxVel>0.0</maxVel>
        <!-- slip complience -->
        <slipComplianceLateral>0.1</slipComplianceLateral>
        <slipComplianceLongitudinal>0.1</slipComplianceLongitudinal>
      </config_params>

      <wheel link_name="front_left_wheel">
        <wheel_normal_force>3315</wheel_normal_force>
      </wheel>
      <wheel link_name="front_right_wheel">
        <wheel_normal_force>3315</wheel_normal_force>
      </wheel>
      <wheel link_name="rear_left_wheel">
        <wheel_normal_force>3315</wheel_normal_force>
      </wheel>
      <wheel link_name="rear_right_wheel">
        <wheel_normal_force>3315</wheel_normal_force>
      </wheel>

      <imu_link link_name="imu_link">
        <wheel_normal_force>3315</wheel_normal_force>
      </imu_link>
    </plugin>
    
    <!-- ************************************************************************ -->
    <!-- OLD GAZEBO ROS SLIP PLUG-IN ******************************************** -->
    <!-- ************************************************************************ -->

    <!-- <plugin filename="libgazebo_wheel_slip_plugin.so" name="wheel_slip">
      <wheel link_name="front_left_wheel">
        <slip_compliance_lateral>0.1</slip_compliance_lateral>
        <slip_compliance_longitudinal>0.1</slip_compliance_longitudinal>
        <wheel_normal_force>3315</wheel_normal_force>
      </wheel>
      <wheel link_name="front_right_wheel">
        <slip_compliance_lateral>0.1</slip_compliance_lateral>
        <slip_compliance_longitudinal>0.1</slip_compliance_longitudinal>
        <wheel_normal_force>3315</wheel_normal_force>
      </wheel>
      <wheel link_name="rear_left_wheel">
        <slip_compliance_lateral>0.1</slip_compliance_lateral>
        <slip_compliance_longitudinal>0.1</slip_compliance_longitudinal>
        <wheel_normal_force>3315</wheel_normal_force>
      </wheel>
      <wheel link_name="rear_right_wheel">
        <slip_compliance_lateral>0.1</slip_compliance_lateral>
        <slip_compliance_longitudinal>0.1</slip_compliance_longitudinal>
        <wheel_normal_force>3315</wheel_normal_force>
      </wheel>
    </plugin> -->


    <!-- BE CARUFEL WITH THIS -->   
    <!-- THE_ONE_USED -->
    <!-- <plugin filename="libWheelSlipPlugin.so" name="wheel_slip">
      <wheel link_name="front_left_wheel">
        <slip_compliance_lateral>0.15</slip_compliance_lateral>
        <slip_compliance_longitudinal>0.1</slip_compliance_longitudinal>
        <wheel_normal_force>3315</wheel_normal_force>
      </wheel>
      <wheel link_name="front_right_wheel">
        <slip_compliance_lateral>0.15</slip_compliance_lateral>
        <slip_compliance_longitudinal>0.1</slip_compliance_longitudinal>
        <wheel_normal_force>3315</wheel_normal_force>
      </wheel>
      <wheel link_name="rear_left_wheel">
        <slip_compliance_lateral>0.01</slip_compliance_lateral>
        <slip_compliance_longitudinal>0.15</slip_compliance_longitudinal>
        <wheel_normal_force>3315</wheel_normal_force>
      </wheel>
      <wheel link_name="rear_right_wheel">
        <slip_compliance_lateral>0.01</slip_compliance_lateral>
        <slip_compliance_longitudinal>0.15</slip_compliance_longitudinal>
        <wheel_normal_force>3315</wheel_normal_force>
      </wheel>
    </plugin> -->

    <!-- ************************************************************************ -->
    <!-- ACKERMANN DRIVE PLUG-IN ************************************************ -->
    <!-- ************************************************************************ -->

    <!-- <plugin name='ackermann_drive' filename='libgazebo_ros_ackermann_drive.so'> -->
    <!-- <plugin name='ackermann_drive' filename='libht_nav_gazebo_ros_ackermann_drive.so'> -->
    <plugin name='ackermann_drive' filename='libgazebo_ros_new_ackermann_drive.so'>

      <ros>
        <namespace>kobra_mk5</namespace>
        <remapping>cmd_acc:=cmd_acc</remapping> 
        <remapping>cmd_vel:=cmd_vel</remapping>
        <remapping>odom:=odom</remapping>
        <remapping>distance:=distance</remapping>
      </ros>

      <update_rate>400.0</update_rate>

      <!-- wheels -->
      <front_left_joint>front_left_combined_joint</front_left_joint>
      <front_right_joint>front_right_combined_joint</front_right_joint>
      <rear_left_joint>rear_left_wheel_joint</rear_left_joint>
      <rear_right_joint>rear_right_wheel_joint</rear_right_joint>
      <left_steering_joint>front_left_combined_joint</left_steering_joint>
      <right_steering_joint>front_right_combined_joint</right_steering_joint>
      <steering_wheel_joint>steering_joint</steering_wheel_joint>

      <!-- Max absolute steer angle for tyre in radians-->
      <!-- Any cmd_vel angular z greater than this would be capped -->
      <max_steer>1.0</max_steer>

      <!-- Max absolute steering angle of steering wheel -->
      <max_steering_angle>45.85</max_steering_angle>

      <!-- Max absolute linear speed in m/s -->
      <max_speed>100</max_speed>

      <!-- PID tuning -->
      <!-- <left_steering_pid_gain>425.0 100.59 50.425</left_steering_pid_gain>
      <left_steering_i_range>0.025 0</left_steering_i_range>
      <right_steering_pid_gain>425.0 100.59 50.425</right_steering_pid_gain>
      <right_steering_i_range>0.025 0</right_steering_i_range>
      <linear_velocity_pid_gain>240 40 1</linear_velocity_pid_gain>
      <linear_velocity_i_range>0.025 0</linear_velocity_i_range> -->

      <left_steering_pid_gain>425.0 100.59 50.425</left_steering_pid_gain>
      <left_steering_i_range>0.025 0</left_steering_i_range>
      <right_steering_pid_gain>425.0 100.59 50.425</right_steering_pid_gain>
      <right_steering_i_range>0.025 0</right_steering_i_range>
      <linear_velocity_pid_gain>100 40 1</linear_velocity_pid_gain>
      <linear_velocity_i_range>0.025 0</linear_velocity_i_range>

      <!-- output -->
      <publish_odom>true</publish_odom>
      <publish_odom_tf>true</publish_odom_tf>
      <publish_wheel_tf>true</publish_wheel_tf>
      <publish_distance>true</publish_distance>

      <odometry_frame>odom_demo</odometry_frame>
      <robot_base_frame>chassis</robot_base_frame>
    </plugin>

    <!-- ************************************************************************ -->
    <!-- SENSOR PLUG-INS ******************************************************** -->
    <!-- ************************************************************************ -->

    <plugin name="ht_link_imu_pub" filename="libht_nav_gazebo_ros_link_imu_publisher.so">
      <ros>
        <namespace>kobra_mk5</namespace>
        <!-- <remapping>imu_data_body:=imu_data</remapping>  -->
      </ros>
      <imu_link>imu_link</imu_link>
      <update_rate>100</update_rate>
      <updateRateHZ>100.0</updateRateHZ>
      <!-- # IMU Modelling Specs (ROS-2 Part)
      acc_bias_std    = 5.0   #1.0  # mg 
      gyro_drift_std  = 10.0  #1.0   # deg/hr

      acc_bias_stab_std   = 0.5    # mg 
      gyro_drift_stab_std = 1.0    # deg/hr
      acc_bias_stab_tc    = 1500   # sec
      gyro_drift_stab_tc  = 1500   # sec

      acc_sf_std   = 0.0  # ppm
      gyro_sf_std  = 0.0  # ppm
      acc_mis_std  = 0.0  # rad
      gyro_mis_std = 0.0  # rad

      acc_rw_std  = 0.06  # 0.065; % ft/s/rt-hr
      gyro_rw_std = 0.125 # 0.125; % deg/rt-hr  
      -->
      <AccRWStd>0.06</AccRWStd>
      <GyroRWStd>0.125</GyroRWStd>
      <AccBiasStd>5.0</AccBiasStd>
      <GyroBiasStd>1.0</GyroBiasStd>
      <!-- <AccRWStd>0.065</AccRWStd>
      <GyroRWStd>0.125</GyroRWStd>
      <AccBiasStd>1.0</AccBiasStd>
      <GyroBiasStd>1.0</GyroBiasStd> -->
      <AccSFStd>0.0</AccSFStd>
      <GyroSFStd>0.0</GyroSFStd>
    </plugin>

    <plugin name="ht_link_gps_pub" filename="libht_nav_gazebo_ros_link_gps_publisher.so">
      <ros>
        <namespace>kobra_mk5</namespace>
      </ros>
      <!-- # GPS Error Modelling Specs (ROS-2 Part)
      config.updateRateHZ = 5.0
      config.posDriftFreq = 500.0;
      config.posBiasStd   = 0.25; 
      config.posDriftStd  = 1.5; 
      config.velErrStd    = 0.10;  
      -->
      <update_rate>5</update_rate>
      <imu_link>imu_link</imu_link>
      <posDriftFreq>500.0</posDriftFreq>  
      <gaussianNoise>0.0</gaussianNoise>  
      <posBiasStd>0.25</posBiasStd>  
      <posDriftStd>1.5</posDriftStd>  
      <velErrStd>0.10</velErrStd>  
    </plugin>
        
    <plugin name="ht_link_state_pub" filename="libht_nav_gazebo_ros_link_state_publisher.so">
      <ros>
        <namespace>kobra_mk5</namespace>
        <!-- <remapping>~/out:=link_states</remapping> -->
      </ros>
      <update_rate>100</update_rate>
      <front_right_wheel>front_right_wheel</front_right_wheel>
      <front_left_wheel>front_left_wheel</front_left_wheel>
      <!-- <front_left_wheel>front_left_wheel_contact</front_left_wheel> -->
      <rear_right_wheel>rear_right_wheel</rear_right_wheel>
      <rear_left_wheel>rear_left_wheel</rear_left_wheel>
      <imu_link>imu_link</imu_link>
    </plugin>

    <plugin name="ht_joint_state_pub" filename="libht_nav_gazebo_ros_joint_state_publisher.so">
      <ros>
        <namespace>kobra_mk5</namespace>
        <remapping>~/out:=joint_states</remapping>
      </ros>
      <update_rate>100</update_rate>
      <joint_name>front_left_combined_joint</joint_name>
      <joint_name>front_right_combined_joint</joint_name>
      <joint_name>rear_left_wheel_joint</joint_name>
      <joint_name>rear_right_wheel_joint</joint_name>
      <joint_name>steering_joint</joint_name>
    </plugin>

    <!-- ************************************************************************ -->
    <!-- CAMERA LINK & PLUG-IN ************************************************** -->          
    <!-- ************************************************************************ -->

    <link name="camera_link">
      <pose relative_to="chassis">0 -0.35 1.5 0 0 -1.57079</pose>
      <sensor type="camera" name="camera1">
        <update_rate>24.0</update_rate>
        <camera name="head">
          <horizontal_fov>1.3962634</horizontal_fov>
          <image>
            <width>640</width>
            <height>360</height>
            <format>R8G8B8</format>
          </image>
          <clip>
            <near>0.02</near>
            <far>300</far>
          </clip>
          <noise>
            <type>gaussian</type>
            <!-- Noise is sampled independently per pixel on each frame.
                That pixel's noise value is added to each of its color
                channels, which at that point lie in the range [0,1]. -->
            <mean>0.0</mean>
            <stddev>0.0</stddev>
          </noise>
        </camera>
        <plugin name="camera_controller" filename="libgazebo_ros_camera.so">
          <alwaysOn>true</alwaysOn>
          <updateRate>0.0</updateRate>
          <cameraName>rrbot/camera1</cameraName>
          <imageTopicName>image_raw</imageTopicName>
          <cameraInfoTopicName>camera_info</cameraInfoTopicName>
          <frameName>camera_link</frameName>
          <hackBaseline>0.07</hackBaseline>
          <distortionK1>0.0</distortionK1>
          <distortionK2>0.0</distortionK2>
          <distortionK3>0.0</distortionK3>
          <distortionT1>0.0</distortionT1>
          <distortionT2>0.0</distortionT2>
        </plugin>
      </sensor>
    </link>

  </model>

</sdf>
